<?xml version='1.0'?>

<robot name="robot" xmlns:xacro="http://www.ros.org/wiki/xacro">

  <xacro:property name="cameraSize" value="0.05"/>
  <xacro:property name="cameraMass" value="0.1"/>
  <xacro:include filename="$(find differential_drive_robot_description)/urdf/differential_drive_robot.gazebo" />
  <xacro:include filename="$(find differential_drive_robot_description)/urdf/materials.xacro" />
  <xacro:include filename="$(find differential_drive_robot_description)/urdf/xacro_variables.xacro" />

<!--Links Declaration-->

  <link name='chassis'>
    <pose>0 0 0.1 0 0 0</pose>

    <inertial>
      <mass value="10.0"/>
      <origin xyz="0.0 0 0.1" rpy=" 0 0 0"/>

      <cylinder_inertia m="10" r="${chasis_cylinder_radius}" h="${chasis_cylinder_height}"/>

      <inertia
          ixx="0.5" ixy="0" ixz="0"
          iyy="1.0" iyz="0"
          izz="0.1"
      />
    </inertial>

    <collision name='collision'>
      <geometry>
        <cylinder radius="${chasis_cylinder_radius}" length="${chasis_cylinder_height}"/>
      </geometry>
    </collision>

    <visual name='chassis_visual'>
      <origin xyz="0 0 0" rpy=" 0 0 0"/>
      <geometry>
        <cylinder radius="${chasis_cylinder_radius}" length="${chasis_cylinder_height}"/>
      </geometry>
      <material name="blue"/>
    </visual>


    <collision name='caster_collision'>
      <origin xyz="${chasis_caster_x} ${chasis_caster_y} ${chasis_caster_z}" rpy=" ${chasis_caster_r} ${chasis_caster_p} ${chasis_caster_ya}"/>
      <geometry>
        <sphere radius="${chasis_caster_radius}"/>
      </geometry>
      <surface>
        <friction>
          <ode>
            <mu>0</mu>
            <mu2>0</mu2>
            <slip1>1.0</slip1>
            <slip2>1.0</slip2>
          </ode>
        </friction>
      </surface>
    </collision>

    <visual name='caster_visual'>
      <origin xyz="${chasis_caster_x} ${chasis_caster_y} ${chasis_caster_z}" rpy=" ${chasis_caster_r} ${chasis_caster_p} ${chasis_caster_ya}"/>
      <geometry>
        <sphere radius="${chasis_caster_radius}"/>
      </geometry>
      <material name="orange"/>
    </visual>

    <collision name='caster_collision2'>
      <origin xyz="${chasis_caster2_x} ${chasis_caster2_y} ${chasis_caster2_z}" rpy=" ${chasis_caster2_r} ${chasis_caster2_p} ${chasis_caster2_ya}"/>
      <geometry>
        <sphere radius="${chasis_caster_radius}"/>
      </geometry>
      <surface>
        <friction>
          <ode>
            <mu>0</mu>
            <mu2>0</mu2>
            <slip1>1.0</slip1>
            <slip2>1.0</slip2>
          </ode>
        </friction>
      </surface>
    </collision>

    <visual name='caster2_visual'>
      <origin xyz="${chasis_caster2_x} ${chasis_caster2_y} ${chasis_caster2_z}" rpy=" ${chasis_caster2_r} ${chasis_caster2_p} ${chasis_caster2_ya}"/>
      <geometry>
        <sphere radius="${chasis_caster_radius}"/>
      </geometry>
      <material name="orange"/>
    </visual>
  </link>


  <link name="left_wheel">
    <!--origin xyz="0.1 0.13 0.1" rpy="0 1.5707 1.5707"/-->
    <collision name="collision">
      <origin xyz="${wheel_x} ${wheel_y} ${wheel_z}" rpy="${wheel_r} ${wheel_p} ${wheel_ya}"/>
      <geometry>
        <cylinder radius="${wheel_cylinder_radius}" length="${wheel_cylinder_height}"/>
      </geometry>
    </collision>
    <visual name="left_wheel_visual">
      <origin xyz="${wheel_x} ${wheel_y} ${wheel_z}" rpy="${wheel_r} ${wheel_p} ${wheel_ya}"/>
      <geometry>
        <cylinder radius="${wheel_cylinder_radius}" length="${wheel_cylinder_height}"/>
      </geometry>
      <material name="black"/>
    </visual>
    <inertial>
      <origin xyz="${wheel_x} ${wheel_y} ${wheel_z}" rpy="${wheel_r} ${wheel_p} ${wheel_ya}"/>
      <mass value="5"/>
      <cylinder_inertia m="5" r="${wheel_cylinder_radius}" h="${wheel_cylinder_height}"/>
      <inertia
        ixx="1.0" ixy="0.0" ixz="0.0"
        iyy="1.0" iyz="0.0"
        izz="1.0"/>
    </inertial>
  </link>


  <link name="right_wheel">
    <collision name="collision">
      <origin xyz="${wheel_x} ${wheel_y} ${wheel_z}" rpy="${wheel_r} ${wheel_p} ${wheel_ya}"/>
      <geometry>
        <cylinder radius="${wheel_cylinder_radius}" length="${wheel_cylinder_height}"/>
      </geometry>
    </collision>
    <visual name="right_wheel_visual">
      <origin xyz="${wheel_x} ${wheel_y} ${wheel_z}" rpy="${wheel_r} ${wheel_p} ${wheel_ya}"/>
      <geometry>
        <cylinder radius="${wheel_cylinder_radius}" length="${wheel_cylinder_height}"/>
      </geometry>
      <material name="black"/>
    </visual>
    <inertial>
      <origin xyz="${wheel_x} ${wheel_y} ${wheel_z}" rpy="${wheel_r} ${wheel_p} ${wheel_ya}"/>
      <mass value="5"/>
      <cylinder_inertia m="5" r="${wheel_cylinder_radius}" h="${wheel_cylinder_height}"/>
      <inertia
        ixx="1.0" ixy="0.0" ixz="0.0"
        iyy="1.0" iyz="0.0"
        izz="1.0"/>
    </inertial>
  </link>


<!--Joint Declaration-->

  <joint type="continuous" name="left_wheel_hinge">
    <origin xyz="${left_wheel_x} ${left_wheel_y} ${left_wheel_z}" rpy="0 0 0"/>
    <child link="left_wheel"/>
    <parent link="chassis"/>
    <axis xyz="0 1 0" rpy="0 0 0"/>
    <limit effort="100" velocity="100"/>
    <joint_properties damping="0.0" friction="0.0"/>
  </joint>

  <joint type="continuous" name="right_wheel_hinge">
    <origin xyz="${right_wheel_x} ${right_wheel_y} ${right_wheel_z}" rpy="0 0 0"/>
    <child link="right_wheel"/>
    <parent link="chassis"/>
    <axis xyz="0 1 0" rpy="0 0 0"/>
    <limit effort="100" velocity="100"/>
    <joint_properties damping="0.0" friction="0.0"/>
  </joint>

  <link name="camera1_link">
    <collision>
      <origin xyz="0 0 0" rpy="0 0 0"/>
      <geometry>
        <box size="${cameraSize} ${cameraSize} ${cameraSize}"/>
      </geometry>
    </collision>

    <visual>
      <origin xyz="0 0 0" rpy="0 0 0"/>
      <geometry>
        <box size="${cameraSize} ${cameraSize} ${cameraSize}"/>
      </geometry>
      <material name="green"/>
    </visual>

    <inertial>
      <mass value="${cameraMass}" />
      <origin xyz="0 0 0" rpy="0 0 0"/>
      <box_inertia m="${cameraMass}" x="${cameraSize}" y="${cameraSize}" z="${cameraSize}" />
      <inertia ixx="1e-6" ixy="0" ixz="0" iyy="1e-6" iyz="0" izz="1e-6" />
    </inertial>
  </link>

  <joint name="camera1_joint" type="fixed">
    <axis xyz="0 1 0" />
    <origin xyz=".2 -0.1 0.01" rpy="0 0 -45"/>
    <parent link="chassis"/>
    <child link="camera1_link"/>
  </joint>

  <link name="camera2_link">
    <collision>
      <origin xyz="0 0 0" rpy="0 0 0"/>
      <geometry>
        <box size="${cameraSize} ${cameraSize} ${cameraSize}"/>
      </geometry>
    </collision>

    <visual>
      <origin xyz="0 0 0" rpy="0 0 0"/>
      <geometry>
        <box size="${cameraSize} ${cameraSize} ${cameraSize}"/>
      </geometry>
      <material name="green"/>
    </visual>

    <inertial>
      <mass value="${cameraMass}" />
      <origin xyz="0 0 0" rpy="0 0 0"/>
      <box_inertia m="${cameraMass}" x="${cameraSize}" y="${cameraSize}" z="${cameraSize}" />
      <inertia ixx="1e-6" ixy="0" ixz="0" iyy="1e-6" iyz="0" izz="1e-6" />
    </inertial>
  </link>

  <joint name="camera2_joint" type="fixed">
    <axis xyz="0 1 0" />
    <origin xyz=".2 0.1 0.01" rpy="0 0 -44"/>
    <parent link="chassis"/>
    <child link="camera2_link"/>
  </joint>

  <link name="imu_link">
    <collision>
      <origin xyz="0 0 0" rpy="0 0 0"/>
      <geometry>
        <box size="0.1 0.1 0.1"/>
      </geometry>
    </collision>
    <visual>
      <origin xyz="0 0 0" rpy="0 0 0"/>
      <geometry>
        <box size="0.1 0.1 0.1"/>
      </geometry>
      <material name="grey"/>
    </visual>
    <inertial>
      <mass value="0.01" />
      <origin xyz="0 0 0" rpy="0 0 0"/>
      <box_inertia m="0.01" x="0.1" y="0.1" z="0.1" />
      <inertia ixx="1e-6" ixy="0" ixz="0" iyy="1e-6" iyz="0" izz="1e-6" />
    </inertial>
  </link>
  <joint name="imu_joint" type="fixed">
    <axis xyz="0 1 0" />
    <origin xyz="0 0 0" rpy="0 0 0"/>
    <parent link="chassis"/>
    <child link="imu_link"/>
  </joint>

  
</robot>